Workbook

Sheet 7. Sınıf Denemeol
A1: TÜRKÇE | B1: KAZANIM | C1: A | D1: B
A2: 1 | B2: T.7.3.5.16. Eş sesli kelimelerin anlamlarını ayırt eder. | C2: C | D2: 11
A3: 2 | B3: T.7.3.5.1. Bağlamdan yararlanarak bilmediği kelime ve kelime gruplarının anlamını tahmin eder. | C3: A | D3: 12
A4: 3 | B4: T.7.4.4.3. Metinde boş bırakılan bölümü anlam akışına göre tamamlar. | C4: B | D4: 13
A5: 4 | B5: T.7.3.5.1. Bağlamdan yararlanarak bilmediği kelime ve kelime gruplarının anlamını tahmin eder. | C5: C | D5: 14
A6: 5 | B6: T.7.3.28.2. Cümlede anlatılmak istenileni yorumlar. | C6: D | D6: 15
A7: 6 | B7: T.7.3.37. Metinde kullanılan düşünceyi geliştirme yollarını belirler. | C7: D | D7: 16
A8: 7 | B8: T.7.3.28.16. Cümledeki örtülü anlamı tespit eder. | C8: B | D8: 17
A9: 8 | B9: T.7.4.4.3. Metinde boş bırakılan bölümü anlam akışına göre tamamlar. | C9: D | D9: 18
A10: 9 | B10: T.7.3.17.1. Metnin ana fikrini/ana duygusunu belirler. | C10: C | D10: 19
A11: 10 | B11: T.7.3.17.1. Metnin ana fikrini/ana duygusunu belirler. | C11: C | D11: 20
A12: 11 | B12: T.7.3.17.1. Metnin ana fikrini/ana duygusunu belirler. | C12: D | D12: 1
A13: 12 | B13: T.7.3.28.18. Karışık olarak verilen sözcüklerden cümle oluşturur. | C13: A | D13: 2
... A21: 20 | B21: T.7.3.12.1. Fiillerin anlam özelliklerini fark eder. | C21: B | D21: 10
A22: SOSYAL BİLGİLER | B22: KAZANIM | C22: A | D22: B
A23: 1 | B23: SB.7.1.1. İletişimi etkileyen tutum ve davranışları analiz ederek kendi tutum ve davranışlarını sorgular. | C23: A | D23: 7
A24: 2 | B24: SB.7.1.2. Bireysel ve toplumsal ilişkilerde olumlu iletişim yollarını kullanır. | C24: C | D24: 8
A25: 3 | B25: SB.7.1.3. Medyanın sosyal değişim ve etkileşimdeki rolünü tartışır. | C25: D | D25: 9
A26: 4 | B26: SB.7.1.3. Medyanın sosyal değişim ve etkileşimdeki rolünü tartışır. | C26: B | D26: 10
A27: 5 | B27: SB.7.1.4. İletişim araçlarından yararlanırken haklarını kullanır ve sorumluluklarını yerine getirir. | C27: A | D27: 1
A28: 6 | B28: SB.7.1.4. İletişim araçlarından yararlanırken haklarını kullanır ve sorumluluklarını yerine getirir. | C28: C | D28: 2
A29: 7 | B29: SB.7.2.1. Osmanlı Devleti'nin siyasi güç olarak ortaya çıkış sürecini ve bu süreci etkileyen faktörleri açıklar. | C29: D | D29: 3
A30: 8 | B30: SB.7.2.1. Osmanlı Devleti'nin siyasi güç olarak ortaya çıkış sürecini ve bu süreci etkileyen faktörleri açıklar. | C30: C | D30: 4
A31: 9 | B31: SB.7.2.1. Osmanlı Devleti'nin siyasi güç olarak ortaya çıkış sürecini ve bu süreci etkileyen faktörleri açıklar. | C31: A | D31: 5
A32: 10 | B32: SB.7.1.4. İletişim araçlarından yararlanırken haklarını kullanır ve sorumluluklarını yerine getirir. | C32: B | D32: 6
A33: DİN KÜLTÜRÜ VE AHLAK BİLGİSİ | B33: KAZANIM | C33: A | D33: B
A34: 1 | B34: D.7.1.1. Varlıklar âlemini özelliklerine göre ayırt eder. | C34: A | D34: 5
A35: 2 | B35: D.7.1.2. Melekleri özellikleri ve görevlerine göre sınıflandırır. | C35: C | D35: 6
A36: 3 | B36: D.7.1.2. Melekleri özellikleri ve görevlerine göre sınıflandırır. | C36: C | D36: 7
A37: 4 | B37: D.7.1.2. Melekleri özellikleri ve görevlerine göre sınıflandırır. | C37: B | D37: 8
A38: 5 | B38: D.7.1.2. Melekleri özellikleri ve görevlerine göre sınıflandırır. | C38: D | D38: 9
A39: 6 | B39: D.7.1.2. Melekleri özellikleri ve görevlerine göre sınıflandırır. | C39: D | D39: 10
A40: 7 | B40: D.7.1.4. Ahiret hayatının aşamalarını açıklar. | C40: B | D40: 1
A41: 8 | B41: D.7.1.3. Dünya hayatı ile ahiret hayatı arasındaki ilişkiyi yorumlar. | C41: C | D41: 2
A42: 9 | B42: D.7.1.5. Allah'ın (c.c.) adil, merhametli ve affedici olması ile ahiret inancı arasında ilişki kurar. | C42: B | D42: 3
A43: 10 | B43: D.7.1.4. Ahiret hayatının aşamalarını açıklar. | C43: A | D43: 4
A44: İNGİLİZCE | B44: KAZANIM | C44: A | D44: B
A45: 1 | B45: E.7.1.1. Describing characters/people (Making simple inquiries) | C45: A | D45: 7
A46: 2 | B46: E.7.1.1. Describing characters/people (Making simple inquiries) | C46: A | D46: 8
A47: 3 | B47: E.7.1.1. Describing characters/people (Making simple inquiries) | C47: D | D47: 9
...

Sheet 7. Sınıf Fernus
A1: Sınav Adı | G1: Sınav Türü: | H1: LGS | J1: Yanlış Etkisi: | K1: 3
G2: Sınıf: | H2: 7 | J2: Tavan Puan: | K2: 500
A3: TÜRKÇE | B3: A KiTAPÇIĞI | C3: B | D3: C | E3: D | F3: ALT DERS | G3: KAZANIM ID | H3: KAZANIM KODU | I3: KAZANIM KONU | J3: KAZANIM | K3: VİDEO ÇÖZÜM URL/ID
A4: 1 | B4: ='7. Sınıf Denemeol'!C2 -> C | C4: ='7. Sınıf Denemeol'!D2 -> 11 | D4: =#REF! -> #REF! | E4: =#REF! -> #REF! | F4: TÜRKÇE | H4: =LEFT(J4,FIND(" ",J4)-1) -> T.7.3.5.16. | I4: {=IFERROR(INDEX(A!D:D, MATCH(J4, A!E:E, 0)), "bulunamadı")} -> Sözcükte Anlam | J4: ='7. Sınıf Denemeol'!B2 -> T.7.3.5.16. Eş sesli kelimelerin anlamlarını ayırt eder.
A5: 2 | B5: ='7. Sınıf Denemeol'!C3 -> A | C5: ='7. Sınıf Denemeol'!D3 -> 12 | D5: =#REF! -> #REF! | E5: =#REF! -> #REF! | F5: TÜRKÇE | H5: =LEFT(J5,FIND(" ",J5)-1) -> T.7.3.5.1. | I5: {=IFERROR(INDEX(A!D:D, MATCH(J5, A!E:E, 0)), "bulunamadı")} -> Sözcükte Anlam | J5: ='7. Sınıf Denemeol'!B3 -> T.7.3.5.1. Bağlamdan yararlanarak bilmediği kelime ve kelime gruplarının anlamını tahmin eder.
A6: 3 | B6: ='7. Sınıf Denemeol'!C4 -> B | C6: ='7. Sınıf Denemeol'!D4 -> 13 | D6: =#REF! -> #REF! | E6: =#REF! -> #REF! | F6: TÜRKÇE | H6: =LEFT(J6,FIND(" ",J6)-1) -> T.7.4.4.3. | I6: {=IFERROR(INDEX(A!D:D, MATCH(J6, A!E:E, 0)), "bulunamadı")} -> Paragrafta Anlam | J6: ='7. Sınıf Denemeol'!B4 -> T.7.4.4.3. Metinde boş bırakılan bölümü anlam akışına göre tamamlar.
A7: 4 | B7: ='7. Sınıf Denemeol'!C5 -> C | C7: ='7. Sınıf Denemeol'!D5 -> 14 | D7: =#REF! -> #REF! | E7: =#REF! -> #REF! | F7: TÜRKÇE | H7: =LEFT(J7,FIND(" ",J7)-1) -> T.7.3.5.1. | I7: {=IFERROR(INDEX(A!D:D, MATCH(J7, A!E:E, 0)), "bulunamadı")} -> Sözcükte Anlam | J7: ='7. Sınıf Denemeol'!B5 -> T.7.3.5.1. Bağlamdan yararlanarak bilmediği kelime ve kelime gruplarının anlamını tahmin eder.
A8: 5 | B8: ='7. Sınıf Denemeol'!C6 -> D | C8: ='7. Sınıf Denemeol'!D6 -> 15 | D8: =#REF! -> #REF! | E8: =#REF! -> #REF! | F8: TÜRKÇE | H8: =LEFT(J8,FIND(" ",J8)-1) -> T.7.3.28.2. | I8: {=IFERROR(INDEX(A!D:D, MATCH(J8, A!E:E, 0)), "bulunamadı")} -> Cümlede Anlam | J8: ='7. Sınıf Denemeol'!B6 -> T.7.3.28.2. Cümlede anlatılmak istenileni yorumlar.
A9: 6 | B9: ='7. Sınıf Denemeol'!C7 -> D | C9: ='7. Sınıf Denemeol'!D7 -> 16 | D9: =#REF! -> #REF! | E9: =#REF! -> #REF! | F9: TÜRKÇE | H9: =LEFT(J9,FIND(" ",J9)-1) -> T.7.3.37. | I9: {=IFERROR(INDEX(A!D:D, MATCH(J9, A!E:E, 0)), "bulunamadı")} -> Paragrafta Anlam | J9: ='7. Sınıf Denemeol'!B7 -> T.7.3.37. Metinde kullanılan düşünceyi geliştirme yollarını belirler.
A10: 7 | B10: ='7. Sınıf Denemeol'!C8 -> B | C10: ='7. Sınıf Denemeol'!D8 -> 17 | D10: =#REF! -> #REF! | E10: =#REF! -> #REF! | F10: TÜRKÇE | H10: =LEFT(J10,FIND(" ",J10)-1) -> T.7.3.28.16. | I10: {=IFERROR(INDEX(A!D:D, MATCH(J10, A!E:E, 0)), "bulunamadı")} -> Cümlede Anlam | J10: ='7. Sınıf Denemeol'!B8 -> T.7.3.28.16. Cümledeki örtülü anlamı tespit eder.
A11: 8 | B11: ='7. Sınıf Denemeol'!C9 -> D | C11: ='7. Sınıf Denemeol'!D9 -> 18 | D11: =#REF! -> #REF! | E11: =#REF! -> #REF! | F11: TÜRKÇE | H11: =LEFT(J11,FIND(" ",J11)-1) -> T.7.4.4.3. | I11: {=IFERROR(INDEX(A!D:D, MATCH(J11, A!E:E, 0)), "bulunamadı")} -> Paragrafta Anlam | J11: ='7. Sınıf Denemeol'!B9 -> T.7.4.4.3. Metinde boş bırakılan bölümü anlam akışına göre tamamlar.
A12: 9 | B12: ='7. Sınıf Denemeol'!C10 -> C | C12: ='7. Sınıf Denemeol'!D10 -> 19 | D12: =#REF! -> #REF! | E12: =#REF! -> #REF! | F12: TÜRKÇE | H12: =LEFT(J12,FIND(" ",J12)-1) -> T.7.3.17.1. | I12: {=IFERROR(INDEX(A!D:D, MATCH(J12, A!E:E, 0)), "bulunamadı")} -> Paragrafta Anlam | J12: ='7. Sınıf Denemeol'!B10 -> T.7.3.17.1. Metnin ana fikrini/ana duygusunu belirler.
A13: 10 | B13: ='7. Sınıf Denemeol'!C11 -> C | C13: ='7. Sınıf Denemeol'!D11 -> 20 | D13: =#REF! -> #REF! | E13: =#REF! -> #REF! | F13: TÜRKÇE | H13: =LEFT(J13,FIND(" ",J13)-1) -> T.7.3.17.1. | I13: {=IFERROR(INDEX(A!D:D, MATCH(J13, A!E:E, 0)), "bulunamadı")} -> Paragrafta Anlam | J13: ='7. Sınıf Denemeol'!B11 -> T.7.3.17.1. Metnin ana fikrini/ana duygusunu belirler.
A14: 11 | B14: ='7. Sınıf Denemeol'!C12 -> D | C14: ='7. Sınıf Denemeol'!D12 -> 1 | D14: =#REF! -> #REF! | E14: =#REF! -> #REF! | F14: TÜRKÇE | H14: =LEFT(J14,FIND(" ",J14)-1) -> T.7.3.17.1. | I14: {=IFERROR(INDEX(A!D:D, MATCH(J14, A!E:E, 0)), "bulunamadı")} -> Paragrafta Anlam | J14: ='7. Sınıf Denemeol'!B12 -> T.7.3.17.1. Metnin ana fikrini/ana duygusunu belirler.
A15: 12 | B15: ='7. Sınıf Denemeol'!C13 -> A | C15: ='7. Sınıf Denemeol'!D13 -> 2 | D15: =#REF! -> #REF! | E15: =#REF! -> #REF! | F15: TÜRKÇE | H15: =LEFT(J15,FIND(" ",J15)-1) -> T.7.3.28.18. | I15: {=IFERROR(INDEX(A!D:D, MATCH(J15, A!E:E, 0)), "bulunamadı")} -> Cümlede Anlam | J15: ='7. Sınıf Denemeol'!B13 -> T.7.3.28.18. Karışık olarak verilen sözcüklerden cümle oluşturur.
... A23: 20 | B23: ='7. Sınıf Denemeol'!C21 -> B | C23: ='7. Sınıf Denemeol'!D21 -> 10 | D23: =#REF! -> #REF! | E23: =#REF! -> #REF! | F23: TÜRKÇE | H23: =LEFT(J23,FIND(" ",J23)-1) -> T.7.3.12.1. | I23: {=IFERROR(INDEX(A!D:D, MATCH(J23, A!E:E, 0)), "bulunamadı")} -> Fiillerin Anlam Özellikleri | J23: ='7. Sınıf Denemeol'!B21 -> T.7.3.12.1. Fiillerin anlam özelliklerini fark eder.
A24: İNKILAP TARİHİ | B24: A KiTAPÇIĞI | C24: B | D24: C | E24: D | F24: ALT DERSİ | G24: KAZANIM ID | H24: KAZANIM KODU | I24: KAZANIM KONU | J24: KAZANIM | K24: VİDEO ÇÖZÜM URL/ID
A25: 1 | B25: ='7. Sınıf Denemeol'!C23 -> A | C25: ='7. Sınıf Denemeol'!D23 -> 7 | D25: =#REF! -> #REF! | E25: =#REF! -> #REF! | F25: SOSYAL BİLGİLER | H25: =LEFT(J25,FIND(" ",J25)-1) -> SB.7.1.1. | I25: {=IFERROR(INDEX(A!D:D, MATCH(J25, A!E:E, 0)), "bulunamadı")} -> İnsandan İnsana Giden Yol | J25: ='7. Sınıf Denemeol'!B23 -> SB.7.1.1. İletişimi etkileyen tutum ve davranışları analiz ederek kendi tutum ve davranışlarını sorgular.
A26: 2 | B26: ='7. Sınıf Denemeol'!C24 -> C | C26: ='7. Sınıf Denemeol'!D24 -> 8 | D26: =#REF! -> #REF! | E26: =#REF! -> #REF! | F26: SOSYAL BİLGİLER | H26: =LEFT(J26,FIND(" ",J26)-1) -> SB.7.1.2. | I26: {=IFERROR(INDEX(A!D:D, MATCH(J26, A!E:E, 0)), "bulunamadı")} -> İletişimin Gücü | J26: ='7. Sınıf Denemeol'!B24 -> SB.7.1.2. Bireysel ve toplumsal ilişkilerde olumlu iletişim yollarını kullanır.
A27: 3 | B27: ='7. Sınıf Denemeol'!C25 -> D | C27: ='7. Sınıf Denemeol'!D25 -> 9 | D27: =#REF! -> #REF! | E27: =#REF! -> #REF! | F27: SOSYAL BİLGİLER | H27: =LEFT(J27,FIND(" ",J27)-1) -> SB.7.1.3. | I27: {=IFERROR(INDEX(A!D:D, MATCH(J27, A!E:E, 0)), "bulunamadı")} -> Hızlı İletişim Güçlü Toplum | J27: ='7. Sınıf Denemeol'!B25 -> SB.7.1.3. Medyanın sosyal değişim ve etkileşimdeki rolünü tartışır.
A28: 4 | B28: ='7. Sınıf Denemeol'!C26 -> B | C28: ='7. Sınıf Denemeol'!D26 -> 10 | D28: =#REF! -> #REF! | E28: =#REF! -> #REF! | F28: SOSYAL BİLGİLER | H28: =LEFT(J28,FIND(" ",J28)-1) -> SB.7.1.3. | I28: {=IFERROR(INDEX(A!D:D, MATCH(J28, A!E:E, 0)), "bulunamadı")} -> Hızlı İletişim Güçlü Toplum | J28: ='7. Sınıf Denemeol'!B26 -> SB.7.1.3. Medyanın sosyal değişim ve etkileşimdeki rolünü tartışır.
A29: 5 | B29: ='7. Sınıf Denemeol'!C27 -> A | C29: ='7. Sınıf Denemeol'!D27 -> 1 | D29: =#REF! -> #REF! | E29: =#REF! -> #REF! | F29: SOSYAL BİLGİLER | H29: =LEFT(J29,FIND(" ",J29)-1) -> SB.7.1.4. | I29: {=IFERROR(INDEX(A!D:D, MATCH(J29, A!E:E, 0)), "bulunamadı")} -> İletişim Özgürlüğü | J29: ='7. Sınıf Denemeol'!B27 -> SB.7.1.4. İletişim araçlarından yararlanırken haklarını kullanır ve sorumluluklarını yerine getirir.
A30: 6 | B30: ='7. Sınıf Denemeol'!C28 -> C | C30: ='7. Sınıf Denemeol'!D28 -> 2 | D30: =#REF! -> #REF! | E30: =#REF! -> #REF! | F30: SOSYAL BİLGİLER | H30: =LEFT(J30,FIND(" ",J30)-1) -> SB.7.1.4. | I30: {=IFERROR(INDEX(A!D:D, MATCH(J30, A!E:E, 0)), "bulunamadı")} -> İletişim Özgürlüğü | J30: ='7. Sınıf Denemeol'!B28 -> SB.7.1.4. İletişim araçlarından yararlanırken haklarını kullanır ve sorumluluklarını yerine getirir.
A31: 7 | B31: ='7. Sınıf Denemeol'!C29 -> D | C31: ='7. Sınıf Denemeol'!D29 -> 3 | D31: =#REF! -> #REF! | E31: =#REF! -> #REF! | F31: SOSYAL BİLGİLER | H31: =LEFT(J31,FIND(" ",J31)-1) -> SB.7.2.1. | I31: {=IFERROR(INDEX(A!D:D, MATCH(J31, A!E:E, 0)), "bulunamadı")} -> Beylikten Cihan Devletine | J31: ='7. Sınıf Denemeol'!B29 -> SB.7.2.1. Osmanlı Devleti'nin siyasi güç olarak ortaya çıkış sürecini ve bu süreci etkileyen faktörleri açıklar.
A32: 8 | B32: ='7. Sınıf Denemeol'!C30 -> C | C32: ='7. Sınıf Denemeol'!D30 -> 4 | D32: =#REF! -> #REF! | E32: =#REF! -> #REF! | F32: SOSYAL BİLGİLER | H32: =LEFT(J32,FIND(" ",J32)-1) -> SB.7.2.1. | I32: {=IFERROR(INDEX(A!D:D, MATCH(J32, A!E:E, 0)), "bulunamadı")} -> Beylikten Cihan Devletine | J32: ='7. Sınıf Denemeol'!B30 -> SB.7.2.1. Osmanlı Devleti'nin siyasi güç olarak ortaya çıkış sürecini ve bu süreci etkileyen faktörleri açıklar.
A33: 9 | B33: ='7. Sınıf Denemeol'!C31 -> A | C33: ='7. Sınıf Denemeol'!D31 -> 5 | D33: =#REF! -> #REF! | E33: =#REF! -> #REF! | F33: SOSYAL BİLGİLER | H33: =LEFT(J33,FIND(" ",J33)-1) -> SB.7.2.1. | I33: {=IFERROR(INDEX(A!D:D, MATCH(J33, A!E:E, 0)), "bulunamadı")} -> Beylikten Cihan Devletine | J33: ='7. Sınıf Denemeol'!B31 -> SB.7.2.1. Osmanlı Devleti'nin siyasi güç olarak ortaya çıkış sürecini ve bu süreci etkileyen faktörleri açıklar.
A34: 10 | B34: ='7. Sınıf Denemeol'!C32 -> B | C34: ='7. Sınıf Denemeol'!D32 -> 6 | D34: =#REF! -> #REF! | E34: =#REF! -> #REF! | F34: SOSYAL BİLGİLER | H34: =LEFT(J34,FIND(" ",J34)-1) -> SB.7.1.4. | I34: {=IFERROR(INDEX(A!D:D, MATCH(J34, A!E:E, 0)), "bulunamadı")} -> İletişim Özgürlüğü | J34: ='7. Sınıf Denemeol'!B32 -> SB.7.1.4. İletişim araçlarından yararlanırken haklarını kullanır ve sorumluluklarını yerine getirir.
A35: DİN KÜLTÜRÜ | B35: A KiTAPÇIĞI | C35: B | D35: C | E35: D | F35: ALT DERSİ | G35: KAZANIM ID | H35: KAZANIM KODU | I35: KAZANIM KONU | J35: KAZANIM | K35: VİDEO ÇÖZÜM URL/ID
A36: 1 | B36: ='7. Sınıf Denemeol'!C34 -> A | C36: ='7. Sınıf Denemeol'!D34 -> 5 | D36: =#REF! -> #REF! | E36: =#REF! -> #REF! | F36: DİN KÜLTÜRÜ | H36: =LEFT(J36,FIND(" ",J36)-1) -> D.7.1.1. | I36: {=IFERROR(INDEX(A!D:D, MATCH(J36, A!E:E, 0)), "bulunamadı")} -> Görülen ve Görülemeyen Varlıklar | J36: ='7. Sınıf Denemeol'!B34 -> D.7.1.1. Varlıklar âlemini özelliklerine göre ayırt eder.
A37: 2 | B37: ='7. Sınıf Denemeol'!C35 -> C | C37: ='7. Sınıf Denemeol'!D35 -> 6 | D37: =#REF! -> #REF! | E37: =#REF! -> #REF! | F37: DİN KÜLTÜRÜ | H37: =LEFT(J37,FIND(" ",J37)-1) -> D.7.1.2. | I37: {=IFERROR(INDEX(A!D:D, MATCH(J37, A!E:E, 0)), "bulunamadı")} -> Melekler ve Özellikleri | J37: ='7. Sınıf Denemeol'!B35 -> D.7.1.2. Melekleri özellikleri ve görevlerine göre sınıflandırır.
A38: 3 | B38: ='7. Sınıf Denemeol'!C36 -> C | C38: ='7. Sınıf Denemeol'!D36 -> 7 | D38: =#REF! -> #REF! | E38: =#REF! -> #REF! | F38: DİN KÜLTÜRÜ | H38: =LEFT(J38,FIND(" ",J38)-1) -> D.7.1.2. | I38: {=IFERROR(INDEX(A!D:D, MATCH(J38, A!E:E, 0)), "bulunamadı")} -> Melekler ve Özellikleri | J38: ='7. Sınıf Denemeol'!B36 -> D.7.1.2. Melekleri özellikleri ve görevlerine göre sınıflandırır.
A39: 4 | B39: ='7. Sınıf Denemeol'!C37 -> B | C39: ='7. Sınıf Denemeol'!D37 -> 8 | D39: =#REF! -> #REF! | E39: =#REF! -> #REF! | F39: DİN KÜLTÜRÜ | H39: =LEFT(J39,FIND(" ",J39)-1) -> D.7.1.2. | I39: {=IFERROR(INDEX(A!D:D, MATCH(J39, A!E:E, 0)), "bulunamadı")} -> Melekler ve Özellikleri | J39: ='7. Sınıf Denemeol'!B37 -> D.7.1.2. Melekleri özellikleri ve görevlerine göre sınıflandırır.
A40: 5 | B40: ='7. Sınıf Denemeol'!C38 -> D | C40: ='7. Sınıf Denemeol'!D38 -> 9 | D40: =#REF! -> #REF! | E40: =#REF! -> #REF! | F40: DİN KÜLTÜRÜ | H40: =LEFT(J40,FIND(" ",J40)-1) -> D.7.1.2. | I40: {=IFERROR(INDEX(A!D:D, MATCH(J40, A!E:E, 0)), "bulunamadı")} -> Melekler ve Özellikleri | J40: ='7. Sınıf Denemeol'!B38 -> D.7.1.2. Melekleri özellikleri ve görevlerine göre sınıflandırır.
A41: 6 | B41: ='7. Sınıf Denemeol'!C39 -> D | C41: ='7. Sınıf Denemeol'!D39 -> 10 | D41: =#REF! -> #REF! | E41: =#REF! -> #REF! | F41: DİN KÜLTÜRÜ | H41: =LEFT(J41,FIND(" ",J41)-1) -> D.7.1.2. | I41: {=IFERROR(INDEX(A!D:D, MATCH(J41, A!E:E, 0)), "bulunamadı")} -> Melekler ve Özellikleri | J41: ='7. Sınıf Denemeol'!B39 -> D.7.1.2. Melekleri özellikleri ve görevlerine göre sınıflandırır.
A42: 7 | B42: ='7. Sınıf Denemeol'!C40 -> B | C42: ='7. Sınıf Denemeol'!D40 -> 1 | D42: =#REF! -> #REF! | E42: =#REF! -> #REF! | F42: DİN KÜLTÜRÜ | H42: =LEFT(J42,FIND(" ",J42)-1) -> D.7.1.4. | I42: {=IFERROR(INDEX(A!D:D, MATCH(J42, A!E:E, 0)), "bulunamadı")} -> Ahiret Hayatının Aşamaları | J42: ='7. Sınıf Denemeol'!B40 -> D.7.1.4. Ahiret hayatının aşamalarını açıklar.
A43: 8 | B43: ='7. Sınıf Denemeol'!C41 -> C | C43: ='7. Sınıf Denemeol'!D41 -> 2 | D43: =#REF! -> #REF! | E43: =#REF! -> #REF! | F43: DİN KÜLTÜRÜ | H43: =LEFT(J43,FIND(" ",J43)-1) -> D.7.1.3. | I43: {=IFERROR(INDEX(A!D:D, MATCH(J43, A!E:E, 0)), "bulunamadı")} -> Dünya ve Ahiret Hayatı | J43: ='7. Sınıf Denemeol'!B41 -> D.7.1.3. Dünya hayatı ile ahiret hayatı arasındaki ilişkiyi yorumlar.
A44: 9 | B44: ='7. Sınıf Denemeol'!C42 -> B | C44: ='7. Sınıf Denemeol'!D42 -> 3 | D44: =#REF! -> #REF! | E44: =#REF! -> #REF! | F44: DİN KÜLTÜRÜ | H44: =LEFT(J44,FIND(" ",J44)-1) -> D.7.1.5. | I44: {=IFERROR(INDEX(A!D:D, MATCH(J44, A!E:E, 0)), "bulunamadı")} -> Ahiret İnancının İnsan Davranışlarına Etkisi | J44: ='7. Sınıf Denemeol'!B42 -> D.7.1.5. Allah'ın (c.c.) adil, merhametli ve affedici olması ile ahiret inancı arasında ilişki kurar.
A45: 10 | B45: ='7. Sınıf Denemeol'!C43 -> A | C45: ='7. Sınıf Denemeol'!D43 -> 4 | D45: =#REF! -> #REF! | E45: =#REF! -> #REF! | F45: DİN KÜLTÜRÜ | H45: =LEFT(J45,FIND(" ",J45)-1) -> D.7.1.4. | I45: {=IFERROR(INDEX(A!D:D, MATCH(J45, A!E:E, 0)), "bulunamadı")} -> Ahiret Hayatının Aşamaları | J45: ='7. Sınıf Denemeol'!B43 -> D.7.1.4. Ahiret hayatının aşamalarını açıklar.
A46: İNGİLİZCE | B46: A KiTAPÇIĞI | C46: B | D46: C | E46: D | F46: ALT DERSİ | G46: KAZANIM ID | H46: KAZANIM KODU | I46: KAZANIM KONU | J46: KAZANIM | K46: VİDEO ÇÖZÜM URL/ID
A47: 1 | B47: ='7. Sınıf Denemeol'!C45 -> A | C47: ='7. Sınıf Denemeol'!D45 -> 7 | D47: =#REF! -> #REF! | E47: =#REF! -> #REF! | F47: İNGİLİZCE | H47: =LEFT(J47,FIND(" ",J47)-1) -> E.7.1.1. | I47: {=IFERROR(INDEX(A!D:D, MATCH(J47, A!E:E, 0)), "bulunamadı")} -> Appearance And Personality | J47: ='7. Sınıf Denemeol'!B45 -> E.7.1.1. Describing characters/people (Making simple inquiries)
...

Sheet A
A1: SINIF | B1: DERS | C1: ÜNİTE | D1: KONU | E1: KAZANIM
A2: 7. SINIF | B2: DİN KÜLTÜRÜ VE AHLAK BİLGİSİ | C2: Melek ve Ahiret İnancı | D2: Görülen ve Görülemeyen Varlıklar | E2: D.7.1.1. Varlıklar âlemini özelliklerine göre ayırt eder.
A3: 7. SINIF | B3: DİN KÜLTÜRÜ VE AHLAK BİLGİSİ | C3: Melek ve Ahiret İnancı | D3: Melekler ve Özellikleri | E3: D.7.1.2. Melekleri özellikleri ve görevlerine göre sınıflandırır.
A4: 7. SINIF | B4: DİN KÜLTÜRÜ VE AHLAK BİLGİSİ | C4: Melek ve Ahiret İnancı | D4: Dünya ve Ahiret Hayatı | E4: D.7.1.3. Dünya hayatı ile ahiret hayatı arasındaki ilişkiyi yorumlar.
A5: 7. SINIF | B5: DİN KÜLTÜRÜ VE AHLAK BİLGİSİ | C5: Melek ve Ahiret İnancı | D5: Ahiret Hayatının Aşamaları | E5: D.7.1.4. Ahiret hayatının aşamalarını açıklar.
A6: 7. SINIF | B6: DİN KÜLTÜRÜ VE AHLAK BİLGİSİ | C6: Melek ve Ahiret İnancı | D6: Ahiret İnancının İnsan Davranışlarına Etkisi | E6: D.7.1.5. Allah'ın (c.c.) adil, merhametli ve affedici olması ile ahiret inancı arasında ilişki kurar.
A7: 7. SINIF | B7: DİN KÜLTÜRÜ VE AHLAK BİLGİSİ | C7: Melek ve Ahiret İnancı | D7: Bir Peygamber Tanıyorum: Hz. İsa (A.S.) | E7: D.7.1.6. Hz. İsa'nın (a.s.) hayatını ana hatlarıyla tanır.
A8: 7. SINIF | B8: DİN KÜLTÜRÜ VE AHLAK BİLGİSİ | C8: Melek ve Ahiret İnancı | D8: Bir Sure Tanıyorum: Nâs Suresi ve Anlamı | E8: D.7.1.7. Nâs suresini okur, anlamını söyler.
A9: 7. SINIF | B9: DİN KÜLTÜRÜ VE AHLAK BİLGİSİ | C9: Hac ve Kurban | D9: İslam’da Hac İbadeti ve Önemi | E9: D.7.2.1. İslam'da hac ibadetinin önemini ayet ve hadisler ışığında yorumlar.
A10: 7. SINIF | B10: DİN KÜLTÜRÜ VE AHLAK BİLGİSİ | C10: Hac ve Kurban | D10: Haccın Yapılışı | E10: D.7.2.2. Haccın yapılışını özetler.
A11: 7. SINIF | B11: DİN KÜLTÜRÜ VE AHLAK BİLGİSİ | C11: Hac ve Kurban | D11: Umre ve Önemi | E11: D.7.2.3. Umre ibadeti ve önemini açıklar.
A12: 7. SINIF | B12: DİN KÜLTÜRÜ VE AHLAK BİLGİSİ | C12: Hac ve Kurban | D12: Kurban İbadeti ve Önemi | E12: D.7.2.4. Kurban ibadetini İslam'ın yardımlaşma ve dayanışmaya verdiği önem açısından değerlendirir.
... A342: 7. SINIF | B342: TÜRKÇE | C342: Yazma | D342: Noktalama İşaretleri | E342: T.7.4.16.23. Ünlem, tırnak, ayraç, köşeli ayraç ve kısa çizginin kullanım alanlarını kavrar.
